<?xml version="1.0" encoding="UTF-8" standalone="no"?>
<?pydev-testrun version="1.0"?><pydev-testsuite>
<summary errors="2" failures="0" finished="true" name="Test Run: 3" tests="2" total_time="Finished in: 0.01 secs."/>
<test location="C:\Users\patir\Documents\GitHub\Core-Python-Exercise\Core-Python-Exercise\context_managers\test_implementating_own_contextmanager.py" status="error" test="ContextManagerFileReadTEST.test_file_found_and_readline" time="">
<stdout/>
<stderr><![CDATA[Traceback (most recent call last):
  File "C:\Users\patir\Documents\GitHub\Core-Python-Exercise\Core-Python-Exercise\context_managers\test_implementating_own_contextmanager.py", line 43, in test_file_found_and_readline
    f.write('pati ram yadav')
AttributeError: 'File' object has no attribute 'write'

======================================================================Traceback (most recent call last):
  File "C:\Users\patir\Documents\GitHub\Core-Python-Exercise\Core-Python-Exercise\context_managers\test_implementating_own_contextmanager.py", line 38, in tearDown
    shutil.rmtree(self.test_dir)
  File "C:\PythonDev\Python34\lib\shutil.py", line 482, in rmtree
    return _rmtree_unsafe(path, onerror)
  File "C:\PythonDev\Python34\lib\shutil.py", line 377, in _rmtree_unsafe
    onerror(os.unlink, fullname, sys.exc_info())
  File "C:\PythonDev\Python34\lib\shutil.py", line 375, in _rmtree_unsafe
    os.unlink(fullname)
PermissionError: [WinError 32] The process cannot access the file because it is being used by another process: 'C:\\Users\\patir\\AppData\\Local\\Temp\\tmp6i9oshyb\\test.txt'
]]></stderr>
</test>
<test location="C:\Users\patir\Documents\GitHub\Core-Python-Exercise\Core-Python-Exercise\context_managers\test_implementating_own_contextmanager.py" status="error" test="ContextManagerFileReadTEST.test_file_not_found" time="">
<stdout/>
<stderr><![CDATA[Traceback (most recent call last):
  File "C:\Users\patir\Documents\GitHub\Core-Python-Exercise\Core-Python-Exercise\context_managers\test_implementating_own_contextmanager.py", line 22, in test_file_not_found
    self.assertRaises(IOError, f.read())  # Here is error
io.UnsupportedOperation: not readable
]]></stderr>
</test>
<launch mode="run">
<launch_memento><![CDATA[<?xml version="1.0" encoding="UTF-8" standalone="no"?>
<launchConfiguration local="true" path="Core-Python-Exercise test_implementating_own_contextmanager.py"/>
]]></launch_memento>
</launch>
</pydev-testsuite>
