<?xml version="1.0" encoding="UTF-8" standalone="no"?>
<?pydev-testrun version="1.0"?><pydev-testsuite>
<summary errors="1" failures="0" finished="true" name="Test Run: 0" tests="1" total_time="Finished in: 0.00 secs."/>
<test location="C:\Users\patir\Documents\GitHub\Core-Python-Exercise\Core-Python-Exercise\context_managers\test_implementating_own_contextmanager.py" status="error" test="ContextManagerFileReadTEST.test_file_not_found" time="">
<stdout/>
<stderr><![CDATA[Traceback (most recent call last):
  File "C:\Users\patir\Documents\GitHub\Core-Python-Exercise\Core-Python-Exercise\context_managers\test_implementating_own_contextmanager.py", line 20, in test_file_not_found
    self.assertRaises(IOError, f.read())
io.UnsupportedOperation: not readable
]]></stderr>
</test>
<launch mode="run">
<launch_memento><![CDATA[<?xml version="1.0" encoding="UTF-8" standalone="no"?>
<launchConfiguration local="true" path="Core-Python-Exercise test_implementating_own_contextmanager.py"/>
]]></launch_memento>
</launch>
</pydev-testsuite>
