<?xml version="1.0" encoding="UTF-8" standalone="no"?>
<?pydev-testrun version="1.0"?><pydev-testsuite>
<summary errors="1" failures="0" finished="true" name="Test Run: 8" tests="2" total_time="Finished in: 0.01 secs."/>
<test location="C:\Users\patir\Documents\GitHub\Core-Python-Exercise\Core-Python-Exercise\context_managers\test_implementating_own_contextmanager.py" status="ok" test="ContextManagerFileReadTEST.test_file_found_and_readline" time="0.01">
<stdout><![CDATA[('w',)
()
]]></stdout>
<stderr/>
</test>
<test location="C:\Users\patir\Documents\GitHub\Core-Python-Exercise\Core-Python-Exercise\context_managers\test_implementating_own_contextmanager.py" status="error" test="ContextManagerFileReadTEST.test_file_not_found" time="">
<stdout><![CDATA[('w',)
]]></stdout>
<stderr><![CDATA[Traceback (most recent call last):
  File "C:\Users\patir\Documents\GitHub\Core-Python-Exercise\Core-Python-Exercise\context_managers\test_implementating_own_contextmanager.py", line 22, in test_file_not_found
    self.assertEqual(str(f.read()), 'not readable')  # Here is error
io.UnsupportedOperation: not readable
]]></stderr>
</test>
<launch mode="run">
<launch_memento><![CDATA[<?xml version="1.0" encoding="UTF-8" standalone="no"?>
<launchConfiguration local="true" path="Core-Python-Exercise test_implementating_own_contextmanager.py"/>
]]></launch_memento>
</launch>
</pydev-testsuite>
